<?xml version="1.0" ?>
<robot name="robot" xmlns:xacro="http://www.ros.org/wiki/xacro">

<xacro:include filename="$(find robot_description)/urdf/materials.xacro" />
<xacro:include filename="$(find robot_description)/urdf/robot.trans" />
<xacro:include filename="$(find robot_description)/urdf/robot.gazebo" />
<link name="base_link">
  <inertial>
    <origin xyz="-0.09000000373925139 0.18020901564422104 0.015073742414888944" rpy="0 0 0"/>
    <mass value="2.30970237246439"/>
    <inertia ixx="0.025147" iyy="0.005246" izz="0.030046" ixy="-0.0" iyz="2.3e-05" ixz="0.0"/>
  </inertial>
  <visual>
    <origin xyz="0 0 0" rpy="0 0 0"/>
    <geometry>
      <mesh filename="package://robot_description/meshes/base_link.stl" scale="0.001 0.001 0.001"/>
    </geometry>
    <material name="red"/>
  </visual>
  <!--
  <collision>
    <origin xyz="0 0 0" rpy="0 0 0"/>
    <geometry>
      <mesh filename="package://robot_description/meshes/base_link.stl" scale="0.001 0.001 0.001"/>
    </geometry>
  </collision>
  -->
</link>

<link name="wheel_behind_right_1">
  <inertial>
    <origin xyz="-0.01128923766816145 5.551115123125783e-17 1.734723475976807e-18" rpy="0 0 0"/>
    <mass value="0.3437196887338507"/>
    <inertia ixx="0.00011" iyy="7e-05" izz="7e-05" ixy="0.0" iyz="0.0" ixz="0.0"/>
  </inertial>
  <visual>
    <origin xyz="0.183 -0.295 -0.011" rpy="0 0 0"/>
    <geometry>
      <mesh filename="package://robot_description/meshes/wheel_behind_right_1.stl" scale="0.001 0.001 0.001"/>
    </geometry>
    <material name="yellow"/>
  </visual>
  <collision>
    <origin xyz="0.183 -0.295 -0.011" rpy="0 0 0"/>
    <geometry>
      <mesh filename="package://robot_description/meshes/wheel_behind_right_1.stl" scale="0.001 0.001 0.001"/>
    </geometry>
  </collision>
</link>

<link name="wheel_front_right_1">
  <inertial>
    <origin xyz="-0.011289240544085588 3.858652136423668e-07 -4.86520340636093e-07" rpy="0 0 0"/>
    <mass value="0.3437196887338507"/>
    <inertia ixx="0.00011" iyy="7e-05" izz="7e-05" ixy="0.0" iyz="-0.0" ixz="0.0"/>
  </inertial>
  <visual>
    <origin xyz="0.183 -0.043481 -0.011052" rpy="0 0 0"/>
    <geometry>
      <mesh filename="package://robot_description/meshes/wheel_front_right_1.stl" scale="0.001 0.001 0.001"/>
    </geometry>
    <material name="yellow"/>
  </visual>
  <collision>
    <origin xyz="0.183 -0.043481 -0.011052" rpy="0 0 0"/>
    <geometry>
      <mesh filename="package://robot_description/meshes/wheel_front_right_1.stl" scale="0.001 0.001 0.001"/>
    </geometry>
  </collision>
</link>

<link name="right_steering_1">
  <inertial>
    <origin xyz="-0.0023574800810829133 3.8586521369093907e-07 -0.0051547049471979065" rpy="0 0 0"/>
    <mass value="0.0020349235937285573"/>
    <inertia ixx="0.0" iyy="0.0" izz="0.0" ixy="-0.0" iyz="0.0" ixz="-0.0"/>
  </inertial>
  <visual>
    <origin xyz="0.175052 -0.043481 -0.018" rpy="0 0 0"/>
    <geometry>
      <mesh filename="package://robot_description/meshes/right_steering_1.stl" scale="0.001 0.001 0.001"/>
    </geometry>
    <material name="black"/>
  </visual>
  <collision>
    <origin xyz="0.175052 -0.043481 -0.018" rpy="0 0 0"/>
    <geometry>
      <mesh filename="package://robot_description/meshes/right_steering_1.stl" scale="0.001 0.001 0.001"/>
    </geometry>
  </collision>
</link>

<link name="wheel_behind_left_1">
  <inertial>
    <origin xyz="0.011289237668161436 5.551115123125783e-17 0.0" rpy="0 0 0"/>
    <mass value="0.3437196887338507"/>
    <inertia ixx="0.00011" iyy="7e-05" izz="7e-05" ixy="0.0" iyz="0.0" ixz="0.0"/>
  </inertial>
  <visual>
    <origin xyz="-0.003 -0.295 -0.011" rpy="0 0 0"/>
    <geometry>
      <mesh filename="package://robot_description/meshes/wheel_behind_left_1.stl" scale="0.001 0.001 0.001"/>
    </geometry>
    <material name="yellow"/>
  </visual>
  <collision>
    <origin xyz="-0.003 -0.295 -0.011" rpy="0 0 0"/>
    <geometry>
      <mesh filename="package://robot_description/meshes/wheel_behind_left_1.stl" scale="0.001 0.001 0.001"/>
    </geometry>
  </collision>
</link>

<link name="wheel_front_left_1">
  <inertial>
    <origin xyz="0.011289237981085803 3.858652136840002e-07 1.480239065331651e-07" rpy="0 0 0"/>
    <mass value="0.3437196887338506"/>
    <inertia ixx="0.00011" iyy="7e-05" izz="7e-05" ixy="-0.0" iyz="-0.0" ixz="0.0"/>
  </inertial>
  <visual>
    <origin xyz="-0.003 -0.043481 -0.010892" rpy="0 0 0"/>
    <geometry>
      <mesh filename="package://robot_description/meshes/wheel_front_left_1.stl" scale="0.001 0.001 0.001"/>
    </geometry>
    <material name="yellow"/>
  </visual>
  <collision>
    <origin xyz="-0.003 -0.043481 -0.010892" rpy="0 0 0"/>
    <geometry>
      <mesh filename="package://robot_description/meshes/wheel_front_left_1.stl" scale="0.001 0.001 0.001"/>
    </geometry>
  </collision>
</link>

<link name="left_steering_1">
  <inertial>
    <origin xyz="0.002416096061838381 3.8586521369787796e-07 -0.0052574341556820645" rpy="0 0 0"/>
    <mass value="0.002073508228019929"/>
    <inertia ixx="0.0" iyy="0.0" izz="0.0" ixy="-0.0" iyz="0.0" ixz="0.0"/>
  </inertial>
  <visual>
    <origin xyz="0.005108 -0.043481 -0.018" rpy="0 0 0"/>
    <geometry>
      <mesh filename="package://robot_description/meshes/left_steering_1.stl" scale="0.001 0.001 0.001"/>
    </geometry>
    <material name="black"/>
  </visual>
  <collision>
    <origin xyz="0.005108 -0.043481 -0.018" rpy="0 0 0"/>
    <geometry>
      <mesh filename="package://robot_description/meshes/left_steering_1.stl" scale="0.001 0.001 0.001"/>
    </geometry>
  </collision>
</link>

<link name="base_link_slide_1">
  <inertial>
    <origin xyz="-9.561337288854777e-07 -0.007878873877462195 0.06716724178772196" rpy="0 0 0"/>
    <mass value="1.360104086481715"/>
    <inertia ixx="0.004785" iyy="0.004758" izz="0.000676" ixy="0.0" iyz="-6.6e-05" ixz="0.0"/>
  </inertial>
  <visual>
    <origin xyz="0.09 -0.175 -0.03" rpy="0 0 0"/>
    <geometry>
      <mesh filename="package://robot_description/meshes/base_link_slide_1.stl" scale="0.001 0.001 0.001"/>
    </geometry>
    <material name="red"/>
  </visual>
  <collision>
    <origin xyz="0.09 -0.175 -0.03" rpy="0 0 0"/>
    <geometry>
      <mesh filename="package://robot_description/meshes/base_link_slide_1.stl" scale="0.001 0.001 0.001"/>
    </geometry>
  </collision>
</link>

<link name="link_slide_1">
  <inertial>
    <origin xyz="4.46770416505371e-06 -0.031290443477246035 -1.5255917501511007e-09" rpy="0 0 0"/>
    <mass value="0.19806946909701184"/>
    <inertia ixx="0.000297" iyy="2.9e-05" izz="0.000311" ixy="0.0" iyz="-0.0" ixz="0.0"/>
  </inertial>
  <visual>
    <origin xyz="0.090001 -0.152161 -0.12" rpy="0 0 0"/>
    <geometry>
      <mesh filename="package://robot_description/meshes/link_slide_1.stl" scale="0.001 0.001 0.001"/>
    </geometry>
    <material name="grey"/>
  </visual>
  <collision>
    <origin xyz="0.090001 -0.152161 -0.12" rpy="0 0 0"/>
    <geometry>
      <mesh filename="package://robot_description/meshes/link_slide_1.stl" scale="0.001 0.001 0.001"/>
    </geometry>
  </collision>
</link>

<link name="link_rotate_1">
  <inertial>
    <origin xyz="0.007007510191658614 -0.03477769725571699 1.0712478404339976e-09" rpy="0 0 0"/>
    <mass value="0.056873946328959236"/>
    <inertia ixx="3.2e-05" iyy="4e-06" izz="3.2e-05" ixy="-0.0" iyz="0.0" ixz="-0.0"/>
  </inertial>
  <visual>
    <origin xyz="0.097001 -0.045 -0.12" rpy="0 0 0"/>
    <geometry>
      <mesh filename="package://robot_description/meshes/link_rotate_1.stl" scale="0.001 0.001 0.001"/>
    </geometry>
    <material name="green"/>
  </visual>
  <collision>
    <origin xyz="0.097001 -0.045 -0.12" rpy="0 0 0"/>
    <geometry>
      <mesh filename="package://robot_description/meshes/link_rotate_1.stl" scale="0.001 0.001 0.001"/>
    </geometry>
  </collision>
</link>

<link name="link_gripper_left_1">
  <inertial>
    <origin xyz="0.00417701567042679 -0.013637441028740031 0.003000003114342592" rpy="0 0 0"/>
    <mass value="0.0058998093110918725"/>
    <inertia ixx="0.0" iyy="0.0" izz="0.0" ixy="-0.0" iyz="-0.0" ixz="0.0"/>
  </inertial>
  <visual>
    <origin xyz="0.085 0.048 -0.117" rpy="0 0 0"/>
    <geometry>
      <mesh filename="package://robot_description/meshes/link_gripper_left_1.stl" scale="0.001 0.001 0.001"/>
    </geometry>
    <material name="Orange"/>
  </visual>
  <collision>
    <origin xyz="0.085 0.048 -0.117" rpy="0 0 0"/>
    <geometry>
      <mesh filename="package://robot_description/meshes/link_gripper_left_1.stl" scale="0.001 0.001 0.001"/>
    </geometry>
  </collision>
</link>

<link name="link_gripper_right_1">
  <inertial>
    <origin xyz="-0.004177018263228902 -0.013637441028740142 0.003000003114342703" rpy="0 0 0"/>
    <mass value="0.005899809311091873"/>
    <inertia ixx="0.0" iyy="0.0" izz="0.0" ixy="0.0" iyz="-0.0" ixz="-0.0"/>
  </inertial>
  <visual>
    <origin xyz="0.095 0.048 -0.117" rpy="0 0 0"/>
    <geometry>
      <mesh filename="package://robot_description/meshes/link_gripper_right_1.stl" scale="0.001 0.001 0.001"/>
    </geometry>
    <material name="Orange"/>
  </visual>
  <collision>
    <origin xyz="0.095 0.048 -0.117" rpy="0 0 0"/>
    <geometry>
      <mesh filename="package://robot_description/meshes/link_gripper_right_1.stl" scale="0.001 0.001 0.001"/>
    </geometry>
  </collision>
</link>

<link name="Gripper_1">
  <inertial>
    <origin xyz="0.005000849200019364 -0.01885437082519064 -1.0954679321883987e-05" rpy="0 0 0"/>
    <mass value="0.025324618837182965"/>
    <inertia ixx="2e-06" iyy="1e-06" izz="3e-06" ixy="0.0" iyz="-0.0" ixz="0.0"/>
  </inertial>
  <visual>
    <origin xyz="0.095001 0.025 -0.12" rpy="0 0 0"/>
    <geometry>
      <mesh filename="package://robot_description/meshes/Gripper_1.stl" scale="0.001 0.001 0.001"/>
    </geometry>
    <material name="Orange"/>
  </visual>
  <collision>
    <origin xyz="0.095001 0.025 -0.12" rpy="0 0 0"/>
    <geometry>
      <mesh filename="package://robot_description/meshes/Gripper_1.stl" scale="0.001 0.001 0.001"/>
    </geometry>
  </collision>
</link>

<link name="bulong_2_1">
  <inertial>
    <origin xyz="-0.007000294651160019 -2.982778503357597e-10 3.2037494185344073e-09" rpy="0 0 0"/>
    <mass value="0.009075432857690607"/>
    <inertia ixx="0.0" iyy="0.0" izz="0.0" ixy="-0.0" iyz="0.0" ixz="-0.0"/>
  </inertial>
  <visual>
    <origin xyz="0.083001 0.025 -0.12" rpy="0 0 0"/>
    <geometry>
      <mesh filename="package://robot_description/meshes/bulong_2_1.stl" scale="0.001 0.001 0.001"/>
    </geometry>
    <material name="silver"/>
  </visual>
  <collision>
    <origin xyz="0.083001 0.025 -0.12" rpy="0 0 0"/>
    <geometry>
      <mesh filename="package://robot_description/meshes/bulong_2_1.stl" scale="0.001 0.001 0.001"/>
    </geometry>
  </collision>
</link>

<link name="bulong_1_1">
  <inertial>
    <origin xyz="-0.01000029465115998 2.2348857070531025e-09 -3.501772871672415e-09" rpy="0 0 0"/>
    <mass value="0.01144293708143595"/>
    <inertia ixx="0.0" iyy="1e-06" izz="1e-06" ixy="-0.0" iyz="-0.0" ixz="0.0"/>
  </inertial>
  <visual>
    <origin xyz="0.080001 -0.045 -0.12" rpy="0 0 0"/>
    <geometry>
      <mesh filename="package://robot_description/meshes/bulong_1_1.stl" scale="0.001 0.001 0.001"/>
    </geometry>
    <material name="silver"/>
  </visual>
  <collision>
    <origin xyz="0.080001 -0.045 -0.12" rpy="0 0 0"/>
    <geometry>
      <mesh filename="package://robot_description/meshes/bulong_1_1.stl" scale="0.001 0.001 0.001"/>
    </geometry>
  </collision>
</link>

<link name="imu_1">
  <inertial>
    <origin xyz="1.3877787807814457e-17 0.05000000000000007 0.0025000000000000022" rpy="0 0 0"/>
    <mass value="0.047099999999999996"/>
    <inertia ixx="4e-06" iyy="6e-06" izz="1e-05" ixy="-0.0" iyz="-0.0" ixz="0.0"/>
  </inertial>
  <visual>
    <origin xyz="0.09 -0.0 -0.03" rpy="0 0 0"/>
    <geometry>
      <mesh filename="package://robot_description/meshes/imu_1.stl" scale="0.001 0.001 0.001"/>
    </geometry>
    <material name="blue"/>
  </visual>
  <collision>
    <origin xyz="0.09 -0.0 -0.03" rpy="0 0 0"/>
    <geometry>
      <mesh filename="package://robot_description/meshes/imu_1.stl" scale="0.001 0.001 0.001"/>
    </geometry>
  </collision>
</link>

<link name="laidar_1">
  <inertial>
    <origin xyz="6.938893903907228e-17 -0.0599999999999995 0.0188715560169503" rpy="0 0 0"/>
    <mass value="1.270082631702368"/>
    <inertia ixx="0.000621" iyy="0.000621" izz="0.000832" ixy="-0.0" iyz="0.0" ixz="-0.0"/>
  </inertial>
  <visual>
    <origin xyz="0.09 -0.35 -0.03" rpy="0 0 0"/>
    <geometry>
      <mesh filename="package://robot_description/meshes/laidar_1.stl" scale="0.001 0.001 0.001"/>
    </geometry>
    <material name="black"/>
  </visual>
  <collision>
    <origin xyz="0.09 -0.35 -0.03" rpy="0 0 0"/>
    <geometry>
      <mesh filename="package://robot_description/meshes/laidar_1.stl" scale="0.001 0.001 0.001"/>
    </geometry>
  </collision>
</link>

<joint name="wheel_right_rear" type="continuous">
  <origin xyz="-0.183 0.295 0.011" rpy="0 0 0"/>
  <parent link="base_link"/>
  <child link="wheel_behind_right_1"/>
  <axis xyz="1.0 0.0 0.0"/>
</joint>

<joint name="wheel_right_front" type="continuous">
  <origin xyz="-0.007948 0.0 -0.006948" rpy="0 0 0"/>
  <parent link="right_steering_1"/>
  <child link="wheel_front_right_1"/>
  <axis xyz="1.0 0.0 0.0"/>
</joint>

<joint name="steering_right" type="continuous">
  <origin xyz="-0.175052 0.043481 0.018" rpy="0 0 0"/>
  <parent link="base_link"/>
  <child link="right_steering_1"/>
  <axis xyz="0.0 0.0 -1.0"/>
</joint>

<joint name="wheel_left_rear" type="continuous">
  <origin xyz="0.003 0.295 0.011" rpy="0 0 0"/>
  <parent link="base_link"/>
  <child link="wheel_behind_left_1"/>
  <axis xyz="1.0 0.0 0.0"/>
</joint>

<joint name="wheel_left_front" type="continuous">
  <origin xyz="0.008108 0.0 -0.007108" rpy="0 0 0"/>
  <parent link="left_steering_1"/>
  <child link="wheel_front_left_1"/>
  <axis xyz="1.0 0.0 0.0"/>
</joint>

<joint name="steering_left" type="continuous">
  <origin xyz="-0.005108 0.043481 0.018" rpy="0 0 0"/>
  <parent link="base_link"/>
  <child link="left_steering_1"/>
  <axis xyz="0.0 0.0 -1.0"/>
</joint>

<joint name="base_slide" type="fixed">
  <origin xyz="-0.09 0.175 0.03" rpy="0 0 0"/>
  <parent link="base_link"/>
  <child link="base_link_slide_1"/>
</joint>

<joint name="link_slide" type="prismatic">
  <origin xyz="-1e-06 -0.022839 0.09" rpy="0 0 0"/>
  <parent link="base_link_slide_1"/>
  <child link="link_slide_1"/>
  <axis xyz="0.0 0.0 1.0"/>
  <limit upper="0.05" lower="-0.05" effort="100" velocity="100"/>
  <dynamics damping="1.0" friction="1.0"/>
</joint>

<joint name="link_rotate" type="continuous">
  <origin xyz="-0.007 -0.107161 0.0" rpy="0 0 0"/>
  <parent link="link_slide_1"/>
  <child link="link_rotate_1"/>
  <axis xyz="1 0 0"/>
</joint>

<joint name="gripper_left" type="fixed">
  <origin xyz="0.010001 -0.023 -0.003" rpy="0 0 0"/>
  <parent link="Gripper_1"/>
  <child link="link_gripper_left_1"/>
</joint>

<joint name="gripper_right" type="fixed">
  <origin xyz="1e-06 -0.023 -0.003" rpy="0 0 0"/>
  <parent link="Gripper_1"/>
  <child link="link_gripper_right_1"/>
</joint>

<joint name="bulong_2" type="fixed">
  <origin xyz="0.002 -0.07 0.0" rpy="0 0 0"/>
  <parent link="link_rotate_1"/>
  <child link="Gripper_1"/>
</joint>

<joint name="gripper" type="fixed">
  <origin xyz="0.014 -0.07 0.0" rpy="0 0 0"/>
  <parent link="link_rotate_1"/>
  <child link="bulong_2_1"/>
</joint>

<joint name="bulong_1" type="fixed">
  <origin xyz="0.01 -0.107161 0.0" rpy="0 0 0"/>
  <parent link="link_slide_1"/>
  <child link="bulong_1_1"/>
</joint>

<joint name="imu" type="fixed">
  <origin xyz="-0.09 0.0 0.03" rpy="0 0 0"/>
  <parent link="base_link"/>
  <child link="imu_1"/>
</joint>

<joint name="scan" type="fixed">
  <origin xyz="-0.09 0.35 0.03" rpy="0 0 0"/>
  <parent link="base_link"/>
  <child link="laidar_1"/>
</joint>

</robot>
